Workbook

Sheet Dashboard
B38: ='Income Statement'!C4 -> FY 2021 | C38: ='Income Statement'!D4 -> FY 2022 | D38: ='Income Statement'!E4 -> FY 2023 | E38: ='Income Statement'!F4 -> FY 2024 | F38: ='Income Statement'!G4 -> FY 2025 E | G38: ='Income Statement'!H4 -> FY 2026(E) | H38: ='Income Statement'!I4 -> FY 2027E | I38: ='Income Statement'!J4 -> FY 2028 E | ... L38: ='Income Statement'!M4 -> 0
A39: EBITDA | B39: ='Income Statement'!C20+'Income Statement'!C35 -> 14394 | C39: ='Income Statement'!D20+'Income Statement'!D35 -> 14407 | D39: ='Income Statement'!E20+'Income Statement'!E35 -> 15184 | E39: ='Income Statement'!F20+'Income Statement'!F35 -> 16025 | F39: ='Income Statement'!G20+'Income Statement'!G35 -> 17745.585 | G39: ='Income Statement'!H20+'Income Statement'!H35 -> 18906.278 | H39: ='Income Statement'!I20+'Income Statement'!I35 -> 20126.538 | I39: ='Income Statement'!J20+'Income Statement'!J35 -> 21410.996 | ... K39: ='Income Statement'!L20+'Income Statement'!L35 -> 24191.889
A40: Net Debt | B40: ='Balance Sheet'!C32+'Balance Sheet'!C37+'Balance Sheet'!G38-'Balance Sheet'!C18 -> 34738 | C40: ='Balance Sheet'!D32+'Balance Sheet'!D37-'Balance Sheet'!D18 -> 34117 | D40: ='Balance Sheet'!E32+'Balance Sheet'!E37-'Balance Sheet'!E18 -> 34394 | E40: ='Balance Sheet'!F32+'Balance Sheet'!F37-'Balance Sheet'!F18 -> 35801 | F40: ='Balance Sheet'!G32+'Balance Sheet'!G37-'Balance Sheet'!G18 -> 34585.628 | G40: ='Balance Sheet'!H32+'Balance Sheet'!H37-'Balance Sheet'!H18 -> 33905.893 | H40: ='Balance Sheet'!I32+'Balance Sheet'!I37-'Balance Sheet'!I18 -> 33083.723 | I40: ='Balance Sheet'!J32+'Balance Sheet'!J37-'Balance Sheet'!J18 -> 32119.592 | J40: ='Balance Sheet'!K32+'Balance Sheet'!K37-'Balance Sheet'!K18 -> 31013.05 | K40: ='Balance Sheet'!L32+'Balance Sheet'!L37-'Balance Sheet'!L18 -> 29762.778
A41: Leverage Ratio | B41: =B40/B39 -> 2.4133667 | C41: =C40/C39 -> 2.368085 | D41: =D40/D39 -> 2.2651475 | E41: =E40/E39 -> 2.2340718 | F41: =F40/F39 -> 1.9489709 | G41: =G40/G39 -> 1.7933668 | H41: =H40/H39 -> 1.6437861 | I41: =I40/I39 -> 1.5001447 | ... K41: =K40/K39 -> 1.2302792
A43: FCFF | E43: =DCF!B16 -> 7443.5235 | F43: =DCF!C16 -> 10297.308 | G43: =DCF!D16 -> 10290.819 | H43: =DCF!E16 -> 10994.151 | I43: =DCF!F16 -> 11730.666 | J43: =DCF!G16 -> 12503.3 | K43: =DCF!H16 -> 13315.07
A49: Football Field Metrics
B51: Methodology | C51: MIN Value ($) | D51: Max Value ($) | E51: Space | F51: Bar Length
B53: 52 Week Trading Range | C53: 127 | D53: 163 | E53: =C53 -> 127 | F53: =D53-C53 -> 36
B54: Comps (Pe Ratio) | C54: 145 | D54: 165 | E54: =C54 -> 145 | F54: =D54-C54 -> 20
B55: DCF (Bear Case) | C55: 115 | D55: 135 | E55: =C55 -> 115 | F55: =D55-C55 -> 20
B56: DCF (Base Case) | C56: 140 | D56: 165 | E56: =C56 -> 140 | F56: =D56-C56 -> 25
B57: DCF (Bull Case) | C57: 175 | D57: 195 | E57: =C57 -> 175 | F57: =D57-C57 -> 20
B59: Current share Price | C59: 147 | D59: 147

Sheet Income Statement
B2: Income Statement of Pepsi | M2: (ALL FIGURES IN MILLION USD)
B4: (YE 31-Dec, USDm) | C4: FY 2021 | D4: FY 2022 | E4: FY 2023 | F4: FY 2024 | G4: FY 2025 E | H4: FY 2026(E) | I4: FY 2027E | J4: FY 2028 E | K4: FY 2029 E | L4: FY 2030 E
B6: Gross Sales | C6: 79474 | D6: 86392 | E6: 91471 | F6: 91854 | G6: =F6*(1+G7) -> 97365.24 | H6: =G6*(1+H7) -> 103207.15 | I6: =H6*(1+I7) -> 109399.58 | J6: =I6*(1+J7) -> 115963.56 | K6: =J6*(1+K7) -> 122921.37 | L6: =K6*(1+L7) -> 130296.65
B7: % growth | D7: =(D6-C6)/C6 -> 0.087047336 | E7: =(E6-D6)/D6 -> 0.058790166 | F7: =(F6-E6)/E6 -> 0.0041871194 | G7: 0.06 | H7: 0.06 | I7: 0.06 | J7: 0.06 | K7: 0.06 | L7: 0.06 | XFD7: 0.06
B9: Cost of Goods Sold | C9: -37075 | D9: -40576 | E9: -41881 | F9: -41744 | G9: =G6*G10 -> -43921.1 | H9: =H6*H10 -> -46556.366 | I9: =I6*I10 -> -49349.748 | J9: =J6*J10 -> -52310.733 | K9: =K6*K10 -> -55449.377 | L9: =L6*L10 -> -58776.339
B10: % of Sales | C10: =C9/C6 -> -0.46650477 | D10: =D9/D6 -> -0.46967312 | E10: =E9/E6 -> -0.45786096 | F10: =F9/F6 -> -0.45446034 | G10: =G9/G6 -> -0.45109631 | H10: =H9/H6 -> -0.45109631 | I10: =I9/I6 -> -0.45109631 | J10: =J9/J6 -> -0.45109631 | ... L10: =L9/L6 -> -0.45109631
B12: Gross Profit | C12: =C6+C9 -> 42399 | D12: =D6+D9 -> 45816 | E12: =E6+E9 -> 49590 | F12: =F6+F9 -> 50110 | G12: =G6+G9 -> 53444.14 | H12: =H6+H9 -> 56650.788 | I12: =I6+I9 -> 60049.836 | J12: =J6+J9 -> 63652.826 | ... L12: =L6+L9 -> 71520.315
B14: SG&A | C14: -31237 | D14: -34459 | E14: -36677 | F14: -37190 | G14: =G6*G15 -> -38946.096 | H14: =H6*H15 -> -41282.862 | I14: =I6*I15 -> -43759.833 | J14: =J6*J15 -> -46385.423 | K14: =K6*K15 -> -49168.549 | L14: =L6*L15 -> -52118.662
B15: SG&A % of Sales | C15: =C14/C6 -> -0.39304678 | D15: =D14/D6 -> -0.39886795 | E15: =E14/E6 -> -0.40096861 | F15: =F14/F6 -> -0.40488166 | G15: -0.4 | H15: -0.4 | I15: -0.4 | J15: -0.4 | K15: -0.4 | L15: -0.4
B16: Other expense | C16: 0 | D16: 155 | E16: -927 | F16: -33 | G16: 0 | H16: 0 | I16: 0 | J16: 0 | K16: 0 | L16: 0
B17: medical expenses/income | C17: 522 | D17: 132 | E17: 250 | F17: -22 | G17: 0 | H17: =H6*H18 -> 0 | I17: =I6*I18 -> 0 | J17: =J6*J18 -> 0 | K17: =K6*K18 -> 0 | L17: =L6*L18 -> 0
B18: medical expense % of Sales | C18: =C17/C6 -> 0.0065681858 | D18: =D17/D6 -> 0.0015279193 | E18: =E17/E6 -> 0.0027331067 | F18: =F17/F6 -> -0.00023951053 | G18: 0 | H18: 0 | I18: 0 | J18: 0 | K18: 0 | L18: 0
B20: EBIT | C20: =C6+C9+C14+C17+C16 -> 11684 | D20: =D6+D9+D14+D17+D16 -> 11644 | E20: =E6+E9+E14+E17+E16 -> 12236 | F20: =F6+F9+F14+F17+F16 -> 12865 | G20: =G6+G9+G14+G17 -> 14498.044 | H20: =H6+H9+H14+H17 -> 15367.927 | I20: =I6+I9+I14+I17 -> 16290.002 | J20: =J6+J9+J14+J17 -> 17267.402 | K20: =K6+K9+K14+K17 -> 18303.447 | L20: =L6+L9+L14+L17 -> 19401.653
B21: % margin | C21: =C20/C6 -> 0.14701663 | D21: =D20/D6 -> 0.134781 | E21: =E20/E6 -> 0.13376917 | F21: =F20/F6 -> 0.14005922 | G21: =G20/G6 -> 0.14890369 | H21: =H20/H6 -> 0.14890369 | I21: =I20/I6 -> 0.14890369 | J21: =J20/J6 -> 0.14890369 | ... L21: =L20/L6 -> 0.14890369
B23: Interest Expense | C23: -1863 | D23: -939 | E23: -819 | F23: -919 | G23: =-'Debt Schedule'!G29 -> -1302.84 | H23: =-'Debt Schedule'!H29 -> -1302.84 | I23: =-'Debt Schedule'!I29 -> -1302.84 | J23: =-'Debt Schedule'!J29 -> -1302.84 | K23: =-'Debt Schedule'!K29 -> -1302.84 | L23: =-'Debt Schedule'!L29 -> -1302.84
B25: EBT | C25: =C20+C23 -> 9821 | D25: =D20+D23 -> 10705 | E25: =E20+E23 -> 11417 | F25: =F20+F23 -> 11946 | G25: =G20+G23 -> 13195.204 | H25: =H20+H23 -> 14065.087 | I25: =I20+I23 -> 14987.162 | J25: =J20+J23 -> 15964.562 | ... L25: =L20+L23 -> 18098.813
B26: % margin | C26: =C25/C6 -> 0.12357501 | D26: =D25/D6 -> 0.12391194 | E26: =E25/E6 -> 0.12481552 | F26: =F25/F6 -> 0.13005422 | G26: =G25/G6 -> 0.13552274 | H26: =H25/H6 -> 0.13628015 | I26: =I25/I6 -> 0.13699469 | J26: =J25/J6 -> 0.13766879 | ... L26: =L25/L6 -> 0.13890467
B28: Taxes | C28: -2142 | D28: -1727 | E28: -2262 | F28: -2320 | G28: =G25*G29 -> -2507.0888 | H28: =H25*H29 -> -2672.3665 | I28: =I25*I29 -> -2847.5608 | J28: =J25*J29 -> -3033.2669 | K28: =K25*K29 -> -3230.1152 | L28: =L25*L29 -> -3438.7745
B29: Tax % of EBT | C29: =C28/C25 -> -0.21810406 | D29: =D28/D25 -> -0.16132648 | E29: =E28/E25 -> -0.1981256 | F29: =F28/F25 -> -0.19420727 | G29: -0.19 | H29: -0.19 | I29: -0.19 | J29: -0.19 | K29: -0.19 | L29: -0.19
B31: PAT (Carried over to Retained Earnings) | C31: =C25+C28+C30 -> 7679 | D31: =D25+D28+D30 -> 8978 | E31: =E25+E28+E30 -> 9155 | F31: =F25+F28+F30 -> 9626 | G31: =G25+G28+G30 -> 10688.115 | H31: =H25+H28+H30 -> 11392.72 | I31: =I25+I28+I30 -> 12139.601 | J31: =J25+J28+J30 -> 12931.296 | ... L31: =L25+L28+L30 -> 14660.039
B32: % of Sales | C32: =C31/C6 -> 0.096622795 | D32: =D31/D6 -> 0.10392166 | E32: =E31/E6 -> 0.10008637 | F32: =F31/F6 -> 0.10479674 | G32: =G31/G6 -> 0.10977342 | H32: =H31/H6 -> 0.11038692 | I32: =I31/I6 -> 0.1109657 | J32: =J31/J6 -> 0.11151172 | ... L32: =L31/L6 -> 0.11251278
B35: Depriciation | C35: ='PPE Schedule'!C11 -> 2710 | D35: ='PPE Schedule'!D11 -> 2763 | E35: ='PPE Schedule'!E11 -> 2948 | F35: ='PPE Schedule'!F11 -> 3160 | G35: ='PPE Schedule'!G11 -> 3247.5405 | H35: ='PPE Schedule'!H11 -> 3538.3518 | I35: ='PPE Schedule'!I11 -> 3836.5361 | J35: ='PPE Schedule'!J11 -> 4143.5937 | ... L35: ='PPE Schedule'!L11 -> 4790.2353
B36: Capex | C36: ='PPE Schedule'!C8 -> 4625 | D36: ='PPE Schedule'!D8 -> 5207 | E36: ='PPE Schedule'!E8 -> 5518 | F36: ='PPE Schedule'!F8 -> 5318 | G36: ='PPE Schedule'!G8 -> 5841.9144 | H36: ='PPE Schedule'!H8 -> 6192.4293 | I36: ='PPE Schedule'!I8 -> 6563.975 | J36: ='PPE Schedule'!J8 -> 6957.8135 | ... L36: ='PPE Schedule'!L8 -> 7817.7993
B40: EPS | C40: =C31/C41 -> 5.5284377 | D40: =D31/D41 -> 6.4729632 | E40: =E31/E41 -> 6.6196674 | F40: =F31/F41 -> 6.9854862 | G40: =G31/G41 -> 7.756252 | H40: =H31/H41 -> 8.2675763 | I40: =I31/I41 -> 8.8095801 | J40: =J31/J41 -> 9.3841042 | ... L40: =L31/L41 -> 10.638635
B41: Outstanding Shares | C41: 1389 | D41: 1387 | E41: 1383 | F41: 1378 | G41: 1378 | H41: 1378 | I41: 1378 | J41: 1378 | K41: 1378 | L41: 1378
B43: Dividend Calculation
B44: Dividend Paid | C44: =-'Cash Flow Statement'!C28 -> 5815 | D44: =-'Cash Flow Statement'!D28 -> 6172 | E44: =-'Cash Flow Statement'!E28 -> 6682 | F44: =-'Cash Flow Statement'!F28 -> 7229 | G44: =G31*G45 -> 8026.6346 | H44: =H31*H45 -> 8555.7837 | I44: =I31*I45 -> 9116.6818 | J44: =J31*J45 -> 9711.2337 | K44: =K31*K45 -> 10341.459 | L44: =L31*L45 -> 11009.497
B45: Dividend payout ratio | C45: =C44/C31 -> 0.75726006 | D45: =D44/D31 -> 0.68745823 | E45: =E44/E31 -> 0.72987439 | F45: =F44/F31 -> 0.75098691 | G45: =G44/G31 -> 0.75098691 | H45: =H44/H31 -> 0.75098691 | I45: =I44/I31 -> 0.75098691 | J45: =J44/J31 -> 0.75098691 | ... L45: =L44/L31 -> 0.75098691

Sheet Cash Flow Statement
B2: Cash Flow Statement
B4: (YE 31-Dec, USDm) | C4: ='Income Statement'!C4 -> FY 2021 | D4: ='Income Statement'!D4 -> FY 2022 | E4: ='Income Statement'!E4 -> FY 2023 | F4: ='Income Statement'!F4 -> FY 2024 | G4: ='Income Statement'!G4 -> FY 2025 E | H4: ='Income Statement'!H4 -> FY 2026(E) | I4: ='Income Statement'!I4 -> FY 2027E | J4: ='Income Statement'!J4 -> FY 2028 E | ... L4: ='Income Statement'!L4 -> FY 2030 E
B6: Net Profit | C6: ='Income Statement'!C31 -> 7679 | D6: ='Income Statement'!D31 -> 8978 | E6: ='Income Statement'!E31 -> 9155 | F6: ='Income Statement'!F31 -> 9626 | G6: ='Income Statement'!G31 -> 10688.115 | H6: ='Income Statement'!H31 -> 11392.72 | I6: ='Income Statement'!I31 -> 12139.601 | J6: ='Income Statement'!J31 -> 12931.296 | ... L6: ='Income Statement'!L31 -> 14660.039
B8: Add: Depreciation & Amortisation | C8: 2710 | D8: 2763 | E8: 2948 | F8: 3160 | G8: ='PPE Schedule'!G11 -> 3247.5405 | H8: ='PPE Schedule'!H11 -> 3538.3518 | I8: ='PPE Schedule'!I11 -> 3836.5361 | J8: ='PPE Schedule'!J11 -> 4143.5937 | K8: ='PPE Schedule'!K11 -> 4461.0039 | L8: ='PPE Schedule'!L11 -> 4790.2353
B10: Changes in working capital | C10: 0
B11: Change in Accounts receivables | C11: -651 | D11: ='Balance Sheet'!C16-'Balance Sheet'!D16 -> -1483 | E11: ='Balance Sheet'!D16-'Balance Sheet'!E16 -> -652 | F11: ='Balance Sheet'!E16-'Balance Sheet'!F16 -> 482 | G11: =-'Balance Sheet'!G16+'Balance Sheet'!F16 -> -337.16329 | H11: =-'Balance Sheet'!H16+'Balance Sheet'!G16 -> -640.2098 | I11: =-'Balance Sheet'!I16+'Balance Sheet'!H16 -> -678.62239 | J11: =-'Balance Sheet'!J16+'Balance Sheet'!I16 -> -719.33973 | K11: =-'Balance Sheet'!K16+'Balance Sheet'!J16 -> -762.50011 | L11: =-'Balance Sheet'!L16+'Balance Sheet'!K16 -> -808.25012
B12: Change in Accounts payables | C12: 1762 | D12: ='Balance Sheet'!D36-'Balance Sheet'!C36 -> 2212 | E12: ='Balance Sheet'!E36-'Balance Sheet'!D36 -> 1766 | F12: ='Balance Sheet'!F36-'Balance Sheet'!E36 -> -683 | G12: ='Balance Sheet'!G36-'Balance Sheet'!F36 -> 1687.9001 | H12: ='Balance Sheet'!H36-'Balance Sheet'!G36 -> 1568.514 | I12: ='Balance Sheet'!I36-'Balance Sheet'!H36 -> 1662.6248 | J12: ='Balance Sheet'!J36-'Balance Sheet'!I36 -> 1762.3823 | K12: ='Balance Sheet'!K36-'Balance Sheet'!J36 -> 1868.1253 | L12: ='Balance Sheet'!L36-'Balance Sheet'!K36 -> 1980.2128
B13: Change in Accounts inventory | C13: -582 | D13: ='Balance Sheet'!C17-'Balance Sheet'!D17 -> -875 | E13: ='Balance Sheet'!D17-'Balance Sheet'!E17 -> -112 | F13: ='Balance Sheet'!E17-'Balance Sheet'!F17 -> 28 | G13: =-('Balance Sheet'!G17-'Balance Sheet'!F17) -> -229.26192 | H13: =-('Balance Sheet'!H17-'Balance Sheet'!G17) -> -332.11572 | I13: =-('Balance Sheet'!I17-'Balance Sheet'!H17) -> -352.04266 | J13: =-('Balance Sheet'!J17-'Balance Sheet'!I17) -> -373.16522 | K13: =-('Balance Sheet'!K17-'Balance Sheet'!J17) -> -395.55513 | L13: =-('Balance Sheet'!L17-'Balance Sheet'!K17) -> -419.28844
B14: Change in prepaid expenses | C14: 159 | D14: ='Balance Sheet'!C21-'Balance Sheet'!D21 -> 174 | E14: ='Balance Sheet'!D21-'Balance Sheet'!E21 -> 8 | F14: ='Balance Sheet'!E21-'Balance Sheet'!F21 -> -123 | G14: =-('Balance Sheet'!G21-'Balance Sheet'!F21) -> -52.6524 | H14: =-('Balance Sheet'!H21-'Balance Sheet'!G21) -> -58.419144 | I14: =-('Balance Sheet'!I21-'Balance Sheet'!H21) -> -61.924293 | J14: =-('Balance Sheet'!J21-'Balance Sheet'!I21) -> -65.63975 | K14: =-('Balance Sheet'!K21-'Balance Sheet'!J21) -> -69.578135 | L14: =-('Balance Sheet'!L21-'Balance Sheet'!K21) -> -73.752823
B15: Other Current Asset | C15: 539 | D15: -958 | E15: 329 | F15: 17 | G15: =-('Balance Sheet'!G19-'Balance Sheet'!F19) -> 79.44332 | H15: =-('Balance Sheet'!H19-'Balance Sheet'!G19) -> -40.893401 | I15: =-('Balance Sheet'!I19-'Balance Sheet'!H19) -> -43.347005 | J15: =-('Balance Sheet'!J19-'Balance Sheet'!I19) -> -45.947825 | K15: =-('Balance Sheet'!K19-'Balance Sheet'!J19) -> -48.704695 | L15: =-('Balance Sheet'!L19-'Balance Sheet'!K19) -> -51.626976
B17: Cash Flow from Operating Activities | C17: =SUM(C6:C15) -> 11616 | D17: =SUM(D6:D15) -> 10811 | E17: =SUM(E6:E15) -> 13442 | F17: =SUM(F6:F15) -> 12507 | G17: =SUM(G6:G15) -> 15083.922 | H17: =SUM(H6:H15) -> 15427.948 | I17: =SUM(I6:I15) -> 16502.826 | J17: =SUM(J6:J15) -> 17633.179 | ... L17: =SUM(L6:L15) -> 20077.568
B18: Sale of asset | C18: 166 | D18: 251 | E18: 198 | F18: 342 | G18: 0 | H18: 0 | I18: 0 | J18: 0 | K18: 0 | L18: 0
B19: Capital Expenditure | C19: -4625 | D19: -5207 | E19: -5518 | F19: -5318 | G19: =-'PPE Schedule'!G8 -> -5841.9144 | H19: =-'PPE Schedule'!H8 -> -6192.4293 | I19: =-'PPE Schedule'!I8 -> -6563.975 | J19: =-'PPE Schedule'!J8 -> -6957.8135 | K19: =-'PPE Schedule'!K8 -> -7375.2823 | L19: =-'PPE Schedule'!L8 -> -7817.7993
B20: Short term investing maturity/purchase | C20: 1135 | D20: 141 | E20: -555 | F20: -425 | G20: 0 | H20: 0 | I20: 0 | J20: 0 | K20: 0 | L20: 0
A21: Other Investing activity net | B21: Other Investing Activity | C21: 55 | D21: 2385 | E21: 380 | F21: -71 | G21: 0 | H21: 0 | I21: 0 | J21: 0 | K21: 0 | L21: 0
B22: Cash Flow from Investing Activities | C22: =C19+C20+C21+C18 -> -3269 | D22: =D19+D20+D21+D18 -> -2430 | E22: =E19+E20+E21+E18 -> -5495 | F22: =F19+F20+F21+F18 -> -5472 | G22: =+G19 -> -5841.9144 | H22: =+H19 -> -6192.4293 | I22: =+I19 -> -6563.975 | J22: =+J19 -> -6957.8135 | K22: =+K19 -> -7375.2823 | L22: =+L19 -> -7817.7993
B23: Proceeds of issuance of long term debt | C23: 4122 | D23: 3377 | E23: 5482 | F23: 4042 | G23: 0 | H23: 0 | I23: 0 | J23: 0 | K23: 0 | L23: 0
B24: Debt redemption | C24: -4844 | D24: -1716 | E24: 0 | F24: 0 | G24: 0 | H24: 0 | I24: 0 | J24: 0 | K24: 0 | L24: 0
B25: Proceeds From Revolver borrowing | G25: ='Debt Schedule'!G25 -> 0 | H25: ='Debt Schedule'!H25 -> 0 | I25: ='Debt Schedule'!I25 -> 0 | J25: ='Debt Schedule'!J25 -> 0 | K25: ='Debt Schedule'!K25 -> 0 | L25: ='Debt Schedule'!L25 -> 0
B26: Repayment of borrowing | G26: =-'Debt Schedule'!G24 -> -7082 | H26: =-'Debt Schedule'!H24 -> 0 | I26: =-'Debt Schedule'!I24 -> 0 | J26: =-'Debt Schedule'!J24 -> 0 | K26: =-'Debt Schedule'!K24 -> 0 | L26: =-'Debt Schedule'!L24 -> 0
B27: Debt Repayment-Long | C27: -3455 | D27: -2458 | E27: -3005 | F27: -3886 | G27: ='Debt Schedule'!G12 -> 0 | H27: ='Debt Schedule'!H12 -> 0 | I27: ='Debt Schedule'!I12 -> 0 | J27: ='Debt Schedule'!J12 -> 0 | K27: ='Debt Schedule'!K12 -> 0 | L27: ='Debt Schedule'!L12 -> 0
B28: Dividend | C28: -5815 | D28: -6172 | E28: -6682 | F28: -7229 | G28: =-'Income Statement'!G44 -> -8026.6346 | H28: =-'Income Statement'!H44 -> -8555.7837 | I28: =-'Income Statement'!I44 -> -9116.6818 | J28: =-'Income Statement'!J44 -> -9711.2337 | K28: =-'Income Statement'!K44 -> -10341.459 | L28: =-'Income Statement'!L44 -> -11009.497
A29: Other Financial activity | C29: -788 | D29: -1554 | E29: 1196 | F29: -483 | G29: 0 | H29: 0 | I29: 0 | J29: 0 | K29: 0 | L29: 0
B30: Cash Flow from Financing Activities | C30: =C23+C24+C27+C28+C29 -> -10780 | D30: =D23+D24+D27+D28+D29 -> -8523 | E30: =E23+E24+E27+E28+E29 -> -3009 | F30: =F23+F24+F27+F28+F29 -> -7556 | G30: =SUM(G23:G29) -> -15108.635 | H30: =SUM(H23:H29) -> -8555.7837 | I30: =SUM(I23:I29) -> -9116.6818 | J30: =SUM(J23:J29) -> -9711.2337 | K30: =SUM(K23:K29) -> -10341.459 | L30: =SUM(L23:L29) -> -11009.497
B31: Other B/s reconciliation plug | C31: -111 | D31: -465 | E31: -297 | F31: -687 | G31: 0 | H31: 0 | I31: 0 | J31: 0 | K31: 0 | L31: 0
B32: add: Currency Adjustment | C32: -114 | D32: -35 | E32: 116 | F32: 2 | G32: 0 | H32: 0 | I32: 0 | J32: 0 | K32: 0 | L32: 0
B33: Net Change in cash during the year | C33: =C17+C22+C30+C32+C31 -> -2658 | D33: =D17+D22+D30+D32+D31 -> -642 | E33: =E17+E22+E30+E32+E31 -> 4757 | F33: =F17+F22+F30+F32+F31 -> -1206 | G33: =+G17+G22+G30 -> -5866.6275 | H33: =+H17+H22+H30 -> 679.73493 | I33: =+I17+I22+I30 -> 822.16922 | J33: =+J17+J22+J30 -> 964.13183 | K33: =+K17+K22+K30 -> 1106.5413 | L33: =+L17+L22+L30 -> 1250.272
B34: Add: Opening Cash Flow | C34: 8254 | D34: =+C35 -> 5596 | E34: =+D35 -> 4954 | F34: =+E35 -> 9711 | G34: =F35 -> 8505 | H34: =+G35 -> 2638.3725 | I34: =+H35 -> 3318.1074 | J34: =+I35 -> 4140.2766 | K34: =+J35 -> 5104.4085 | L34: =+K35 -> 6210.9498
B35: Closing Cash Flow | C35: =C33+C34 -> 5596 | D35: =D33+D34 -> 4954 | E35: =E33+E34 -> 9711 | F35: =F33+F34 -> 8505 | G35: =G33+G34 -> 2638.3725 | H35: =H33+H34 -> 3318.1074 | I35: =I33+I34 -> 4140.2766 | J35: =J33+J34 -> 5104.4085 | ... L35: =L33+L34 -> 7461.2218

Sheet Balance Sheet
B2: Balance Sheet
B4: (YE 31-Dec, USDm) | C4: ='Income Statement'!C4 -> FY 2021 | D4: ='Income Statement'!D4 -> FY 2022 | E4: ='Income Statement'!E4 -> FY 2023 | F4: ='Income Statement'!F4 -> FY 2024 | G4: ='Income Statement'!G4 -> FY 2025 E | H4: ='Income Statement'!H4 -> FY 2026(E) | I4: ='Income Statement'!I4 -> FY 2027E | J4: ='Income Statement'!J4 -> FY 2028 E | ... L4: ='Income Statement'!L4 -> FY 2030 E
B6: Assets
A8: =A8:B41 -> 0 | B8: Fixed Assets (PPE) | C8: 22407 | D8: 24291 | E8: 27039 | F8: 28008 | G8: ='PPE Schedule'!G13 -> 30602.374 | H8: ='PPE Schedule'!H13 -> 33256.451 | I8: ='PPE Schedule'!I13 -> 35983.89 | J8: ='PPE Schedule'!J13 -> 38798.11 | K8: ='PPE Schedule'!K13 -> 41712.389 | L8: ='PPE Schedule'!L13 -> 44739.953
B9: Amortization Intangible asset | C9: 1538 | D9: 1277 | E9: 1199 | F9: 1102 | G9: 1102 | H9: 1102 | I9: 1102 | J9: 1102 | K9: 1102 | L9: 1102
B10: Investment in non controlled affiliates | C10: 2350 | D10: 3073 | E10: 2714 | F10: 1985 | G10: 1985 | H10: 1985 | I10: 1985 | J10: 1985 | K10: 1985 | L10: 1985
B11: Deferred Income taxes | C11: 4310 | D11: 4204 | E11: 4474 | F11: 4362 | G11: 4362 | H11: 4362 | I11: 4362 | J11: 4362 | K11: 4362 | L11: 4362
B12: other Assets | C12: 4481 | D12: 5292 | E12: 6661 | F12: 6951 | G12: 6951 | H12: 6951 | I12: 6951 | J12: 6951 | K12: 6951 | L12: 6951
A13: Other Indefinite-lived Intangible Asset | C13: 17127 | D13: 14309 | E13: 13730 | F13: 13699 | G13: 13699 | H13: 13699 | I13: 13699 | J13: 13699 | K13: 13699 | L13: 13699
B14: Goodwill | C14: 18381 | D14: 18202 | E14: 17728 | F14: 17534 | G14: 17534 | H14: 17534 | I14: 17534 | J14: 17534 | K14: 17534 | L14: 17534
B15: Current Assets
B16: Accounts Receivables | C16: 8680 | D16: 10163 | E16: 10815 | F16: 10333 | G16: ='Working capital'!F6 -> 10670.163 | H16: ='Working capital'!G6 -> 11310.373 | I16: ='Working capital'!H6 -> 11988.995 | J16: ='Working capital'!I6 -> 12708.335 | K16: ='Working capital'!J6 -> 13470.835 | L16: ='Working capital'!K6 -> 14279.085
B17: Inventory | C17: 4347 | D17: 5222 | E17: 5334 | F17: 5306 | G17: ='Working capital'!F8 -> 5535.2619 | H17: ='Working capital'!G8 -> 5867.3776 | I17: ='Working capital'!H8 -> 6219.4203 | J17: ='Working capital'!I8 -> 6592.5855 | K17: ='Working capital'!J8 -> 6988.1406 | L17: ='Working capital'!K8 -> 7407.4291
B18: Cash | C18: ='Cash Flow Statement'!C35 -> 5596 | D18: ='Cash Flow Statement'!D35 -> 4954 | E18: ='Cash Flow Statement'!E35 -> 9711 | F18: ='Cash Flow Statement'!F35 -> 8505 | G18: ='Cash Flow Statement'!G35 -> 2638.3725 | H18: ='Cash Flow Statement'!H35 -> 3318.1074 | I18: ='Cash Flow Statement'!I35 -> 4140.2766 | J18: ='Cash Flow Statement'!J35 -> 5104.4085 | ... L18: ='Cash Flow Statement'!L35 -> 7461.2218
B19: other Current Assets | C19: 392 | D19: 394 | E19: 292 | F19: 761 | G19: ='Working capital'!F12 -> 681.55668 | H19: ='Working capital'!G12 -> 722.45008 | I19: ='Working capital'!H12 -> 765.79709 | J19: ='Working capital'!I12 -> 811.74491 | K19: ='Working capital'!J12 -> 860.44961 | L19: ='Working capital'!K12 -> 912.07658
B20: Asset held for sale | C20: 1788 | D20: 0 | E20: 0 | F20: 0 | G20: 0 | H20: 0 | I20: 0 | J20: 0 | K20: 0 | L20: 0
B21: Prepaid Expenses | C21: 980 | D21: 806 | E21: 798 | F21: 921 | G21: ='Working capital'!F10 -> 973.6524 | H21: ='Working capital'!G10 -> 1032.0715 | I21: ='Working capital'!H10 -> 1093.9958 | J21: ='Working capital'!I10 -> 1159.6356 | K21: ='Working capital'!J10 -> 1229.2137 | L21: ='Working capital'!K10 -> 1302.9665
B22: Total Assets | C22: =SUM(C8:C21) -> 92377 | D22: =SUM(D8:D21) -> 92187 | E22: =SUM(E8:E21) -> 100495 | F22: =SUM(F8:F21) -> 99467 | G22: =SUM(G8:G21) -> 96734.381 | H22: =SUM(H8:H21) -> 101139.83 | I22: =SUM(I8:I21) -> 105825.38 | J22: =SUM(J8:J21) -> 110807.82 | ... L22: =SUM(L8:L21) -> 121735.73
B23: Liabilities
B24: Shareholders equity
B25: Capital in excess of par value | C25: 4001 | D25: 4134 | E25: 4261 | F25: 4385 | G25: 4385 | H25: 4385 | I25: 4385 | J25: 4385 | K25: 4385 | L25: 4385
B26: Common Stock | C26: 23 | D26: 23 | E26: 23 | F26: 23 | G26: 23 | H26: 23 | I26: 23 | J26: 23 | K26: 23 | L26: 23
B27: Retained Earnings | C27: =65165 -> 65165 | D27: 67800 | E27: 70035 | F27: 72266 | G27: ='Shareholders equity'!F15 -> 74927.481 | H27: ='Shareholders equity'!G15 -> 77764.417 | I27: ='Shareholders equity'!H15 -> 80787.337 | J27: ='Shareholders equity'!I15 -> 84007.399 | K27: ='Shareholders equity'!J15 -> 87436.431 | L27: ='Shareholders equity'!K15 -> 91086.973
B28: Accumulated comprehensive loss | C28: -14898 | D28: -15302 | E28: -15534 | F28: -17612 | G28: -17612 | H28: -17612 | I28: -17612 | J28: -17612 | K28: -17612 | L28: -17612
B29: Repurchased common stock, in excess of par value (484 and 487 shares, respectively) | C29: -38248 | D29: -39506 | E29: -40282 | F29: -41021 | G29: -41021 | H29: -41021 | I29: -41021 | J29: -41021 | K29: -41021 | L29: -41021
B30: Non controlling interest | C30: 108 | D30: 124 | E30: 134 | F30: 130 | G30: 130 | H30: 130 | I30: 130 | J30: 130 | K30: 130 | L30: 130
B31: Total Equity | C31: =SUM(C25:C30) -> 16151 | D31: =SUM(D25:D30) -> 17273 | E31: =SUM(E25:E30) -> 18637 | F31: =SUM(F25:F30) -> 18171 | G31: =SUM(G25:G30) -> 20832.481 | H31: =SUM(H25:H30) -> 23669.417 | I31: =SUM(I25:I30) -> 26692.337 | J31: =SUM(J25:J30) -> 29912.399 | ... L31: =SUM(L25:L30) -> 36991.973
B32: Long Term Debt | C32: 36026 | D32: 35657 | E32: 37595 | F32: 37224 | G32: ='Debt Schedule'!G19 -> 37224 | H32: ='Debt Schedule'!H19 -> 37224 | I32: ='Debt Schedule'!I19 -> 37224 | J32: ='Debt Schedule'!J19 -> 37224 | K32: ='Debt Schedule'!K19 -> 37224 | L32: ='Debt Schedule'!L19 -> 37224
A33: Other liabilities | B33: Other non-current liability(pension) | C33: 9154 | D33: 8339 | E33: 8721 | F33: 9052 | G33: 9052 | H33: 9052 | I33: 9052 | J33: 9052 | K33: 9052 | L33: 9052
B34: Deferred income tax | C34: 4826 | D34: 4133 | E34: 3895 | F34: 3484 | G34: 3484 | H34: 3484 | I34: 3484 | J34: 3484 | K34: 3484 | L34: 3484
B35: Current Liabilities
B36: Accounts Payables | C36: 21159 | D36: 23371 | E36: 25137 | F36: 24454 | G36: ='Working capital'!F16 -> 26141.9 | H36: ='Working capital'!G16 -> 27710.414 | I36: ='Working capital'!H16 -> 29373.039 | J36: ='Working capital'!I16 -> 31135.421 | K36: ='Working capital'!J16 -> 33003.547 | L36: ='Working capital'!K16 -> 34983.759
B37: Short term debt obligation | C37: 4308 | D37: 3414 | E37: 6510 | F37: 7082
B38: Revolver credit facility | G38: ='Debt Schedule'!G26 -> 0 | H38: ='Debt Schedule'!H26 -> 0 | I38: ='Debt Schedule'!I26 -> 0 | J38: ='Debt Schedule'!J26 -> 0 | K38: ='Debt Schedule'!K26 -> 0 | L38: ='Debt Schedule'!L26 -> 0
B39: Liabilities held for sale | C39: 753 | D39: 0 | E39: 0 | F39: 0 | G39: 0 | H39: 0 | I39: 0 | J39: 0 | K39: 0 | L39: 0
B40: Total Liabilities | C40: =SUM(C32:C39) -> 76226 | D40: =SUM(D32:D39) -> 74914 | E40: =SUM(E32:E39) -> 81858 | F40: =SUM(F32:F39) -> 81296 | G40: =SUM(G32:G38) -> 75901.9 | H40: =SUM(H32:H39) -> 77470.414 | I40: =SUM(I32:I39) -> 79133.039 | J40: =SUM(J32:J39) -> 80895.421 | K40: =SUM(K32:K39) -> 82763.547 | L40: =SUM(L32:L39) -> 84743.759
B41: Total Liabilities and Equity | C41: =SUM(C40+C31) -> 92377 | D41: =SUM(D40+D31) -> 92187 | E41: =SUM(E40+E31) -> 100495 | F41: =SUM(F40+F31) -> 99467 | G41: =SUM(G40+G31) -> 96734.381 | H41: =SUM(H40+H31) -> 101139.83 | I41: =SUM(I40+I31) -> 105825.38 | J41: =SUM(J40+J31) -> 110807.82 | ... L41: =SUM(L40+L31) -> 121735.73
C43: =C22-C41 -> 0 | D43: =D22-D41 -> 0 | E43: =E22-E41 -> 0 | F43: =F22-F41 -> 0 | G43: =G22-G41 -> 0 | H43: =H22-H41 -> 0 | I43: =I22-I41 -> 0 | J43: =J22-J41 -> 0 | ... L43: =L22-L41 -> 0

Sheet Shareholders equity
B1: ='Income Statement'!C4 -> FY 2021 | C1: ='Income Statement'!D4 -> FY 2022 | D1: ='Income Statement'!E4 -> FY 2023 | E1: ='Income Statement'!F4 -> FY 2024 | F1: ='Income Statement'!G4 -> FY 2025 E | G1: ='Income Statement'!H4 -> FY 2026(E) | H1: ='Income Statement'!I4 -> FY 2027E | I1: ='Income Statement'!J4 -> FY 2028 E | ... K1: ='Income Statement'!L4 -> FY 2030 E
A2: Common stock | B2: ='Balance Sheet'!C26 -> 23 | C2: ='Balance Sheet'!D26 -> 23 | D2: ='Balance Sheet'!E26 -> 23 | E2: ='Balance Sheet'!F26 -> 23 | F2: ='Balance Sheet'!G26 -> 23 | G2: ='Balance Sheet'!H26 -> 23 | H2: ='Balance Sheet'!I26 -> 23 | I2: ='Balance Sheet'!J26 -> 23 | ... K2: ='Balance Sheet'!L26 -> 23
A3: Capital in excess of par value | B3: ='Balance Sheet'!C25 -> 4001 | C3: ='Balance Sheet'!D25 -> 4134 | D3: ='Balance Sheet'!E25 -> 4261 | E3: ='Balance Sheet'!F25 -> 4385 | F3: ='Balance Sheet'!G25 -> 4385 | G3: ='Balance Sheet'!H25 -> 4385 | H3: ='Balance Sheet'!I25 -> 4385 | I3: ='Balance Sheet'!J25 -> 4385 | ... K3: ='Balance Sheet'!L25 -> 4385
A4: Accumulated comprehensive loss | B4: ='Balance Sheet'!C28 -> -14898 | C4: ='Balance Sheet'!D28 -> -15302 | D4: ='Balance Sheet'!E28 -> -15534 | E4: ='Balance Sheet'!F28 -> -17612 | F4: ='Balance Sheet'!G28 -> -17612 | G4: ='Balance Sheet'!H28 -> -17612 | H4: ='Balance Sheet'!I28 -> -17612 | I4: ='Balance Sheet'!J28 -> -17612 | ... K4: ='Balance Sheet'!L28 -> -17612
A5: Repurchased common stock, in excess of par value (484 and 487 shares, respectively) | B5: ='Balance Sheet'!C29 -> -38248 | C5: ='Balance Sheet'!D29 -> -39506 | D5: ='Balance Sheet'!E29 -> -40282 | E5: ='Balance Sheet'!F29 -> -41021 | F5: ='Balance Sheet'!G29 -> -41021 | G5: ='Balance Sheet'!H29 -> -41021 | H5: ='Balance Sheet'!I29 -> -41021 | I5: ='Balance Sheet'!J29 -> -41021 | ... K5: ='Balance Sheet'!L29 -> -41021
A6: Non controlling interest | B6: ='Balance Sheet'!C30 -> 108 | C6: ='Balance Sheet'!D30 -> 124 | D6: ='Balance Sheet'!E30 -> 134 | E6: ='Balance Sheet'!F30 -> 130 | F6: ='Balance Sheet'!G30 -> 130 | G6: ='Balance Sheet'!H30 -> 130 | H6: ='Balance Sheet'!I30 -> 130 | I6: ='Balance Sheet'!J30 -> 130 | ... K6: ='Balance Sheet'!L30 -> 130
A7: Total | B7: =SUM(B2:B6) -> -49014 | C7: =SUM(C2:C6) -> -50527 | D7: =SUM(D2:D6) -> -51398 | E7: =SUM(E2:E6) -> -54095 | F7: =SUM(F2:F6) -> -54095 | G7: =SUM(G2:G6) -> -54095 | H7: =SUM(H2:H6) -> -54095 | I7: =SUM(I2:I6) -> -54095 | ... K7: =SUM(K2:K6) -> -54095
A9: Retained Earning
A11: Beginning balance | C11: =B15 -> 65165 | D11: =C15 -> 67800 | E11: =D15 -> 70035 | F11: =E15 -> 72266 | G11: =F15 -> 74927.481 | H11: =G15 -> 77764.417 | I11: =H15 -> 80787.337 | J11: =I15 -> 84007.399 | K11: =J15 -> 87436.431
A12: ADD: Income | F12: ='Income Statement'!G31 -> 10688.115 | G12: ='Income Statement'!H31 -> 11392.72 | H12: ='Income Statement'!I31 -> 12139.601 | I12: ='Income Statement'!J31 -> 12931.296 | J12: ='Income Statement'!K31 -> 13770.491 | K12: ='Income Statement'!L31 -> 14660.039
A13: Less: Dividend | F13: ='Cash Flow Statement'!G28 -> -8026.6346 | G13: ='Cash Flow Statement'!H28 -> -8555.7837 | H13: ='Cash Flow Statement'!I28 -> -9116.6818 | I13: ='Cash Flow Statement'!J28 -> -9711.2337 | J13: ='Cash Flow Statement'!K28 -> -10341.459 | K13: ='Cash Flow Statement'!L28 -> -11009.497
A14: Stock Repurchase | F14: 0 | G14: 0 | H14: 0 | I14: 0 | J14: 0 | K14: 0
A15: End balance | B15: ='Balance Sheet'!C27 -> 65165 | C15: ='Balance Sheet'!D27 -> 67800 | D15: ='Balance Sheet'!E27 -> 70035 | E15: ='Balance Sheet'!F27 -> 72266 | F15: =SUM(F11:F13) -> 74927.481 | G15: =SUM(G11:G13) -> 77764.417 | H15: =SUM(H11:H13) -> 80787.337 | I15: =SUM(I11:I13) -> 84007.399 | J15: =SUM(J11:J13) -> 87436.431 | K15: =SUM(K11:K13) -> 91086.973
A17: Total Equity | B17: =B7+B15 -> 16151 | C17: =C7+C15 -> 17273 | D17: =D7+D15 -> 18637 | E17: =E7+E15 -> 18171 | F17: =F7+F15 -> 20832.481 | G17: =G7+G15 -> 23669.417 | H17: =H7+H15 -> 26692.337 | I17: =I7+I15 -> 29912.399 | ... K17: =K7+K15 -> 36991.973

Sheet Working capital
B1: ='Income Statement'!C4 -> FY 2021 | C1: ='Income Statement'!D4 -> FY 2022 | D1: ='Income Statement'!E4 -> FY 2023 | E1: ='Income Statement'!F4 -> FY 2024 | F1: ='Income Statement'!G4 -> FY 2025 E | G1: ='Income Statement'!H4 -> FY 2026(E) | H1: ='Income Statement'!I4 -> FY 2027E | I1: ='Income Statement'!J4 -> FY 2028 E | ... K1: ='Income Statement'!L4 -> FY 2030 E
A3: Net Sales | B3: ='Income Statement'!C6 -> 79474 | C3: ='Income Statement'!D6 -> 86392 | D3: ='Income Statement'!E6 -> 91471 | E3: ='Income Statement'!F6 -> 91854 | F3: ='Income Statement'!G6 -> 97365.24 | G3: ='Income Statement'!H6 -> 103207.15 | H3: ='Income Statement'!I6 -> 109399.58 | I3: ='Income Statement'!J6 -> 115963.56 | ... K3: ='Income Statement'!L6 -> 130296.65 | N3: FY2021 | O3: FY2022 | P3: FY2023 | Q3: FY2024
A4: COGS | B4: ='Income Statement'!C9 -> -37075 | C4: ='Income Statement'!D9 -> -40576 | D4: ='Income Statement'!E9 -> -41881 | E4: ='Income Statement'!F9 -> -41744 | F4: ='Income Statement'!G9 -> -43921.1 | G4: ='Income Statement'!H9 -> -46556.366 | H4: ='Income Statement'!I9 -> -49349.748 | I4: ='Income Statement'!J9 -> -52310.733 | ... K4: ='Income Statement'!L9 -> -58776.339
A6: Account Receivable | B6: ='Balance Sheet'!C16 -> 8680 | C6: ='Balance Sheet'!D16 -> 10163 | D6: ='Balance Sheet'!E16 -> 10815 | E6: ='Balance Sheet'!F16 -> 10333 | F6: =F3*F7/365 -> 10670.163 | G6: =G3*G7/365 -> 11310.373 | H6: =H3*H7/365 -> 11988.995 | I6: =I3*I7/365 -> 12708.335 | J6: =J3*J7/365 -> 13470.835 | K6: =K3*K7/365 -> 14279.085 | M6: Days Sale outstanding | N6: =B6/B3*365 -> 39.86461 | O6: =(C6/C3)*365 -> 42.937946 | P6: =(D6/D3)*365 -> 43.155481 | Q6: =(E6/E3)*365 -> 41.060215
A7: Days Outstanding | B7: =N6 -> 39.86461 | C7: =O6 -> 42.937946 | D7: =P6 -> 43.155481 | E7: =Q6 -> 41.060215 | F7: 40 | G7: 40 | H7: 40 | I7: 40 | J7: 40 | K7: 40
A8: Inventory | B8: ='Balance Sheet'!C17 -> 4347 | C8: ='Balance Sheet'!D17 -> 5222 | D8: ='Balance Sheet'!E17 -> 5334 | E8: ='Balance Sheet'!F17 -> 5306 | F8: =(F4*F9/365)*-1 -> 5535.2619 | G8: =(G4*G9/365)*-1 -> 5867.3776 | H8: =(H4*H9/365)*-1 -> 6219.4203 | I8: =(I4*I9/365)*-1 -> 6592.5855 | J8: =(J4*J9/365)*-1 -> 6988.1406 | K8: =(K4*K9/365)*-1 -> 7407.4291 | M8: Days inventory outstanding | N8: =(B8/B4*365)*-1 -> 42.795819 | O8: =(C8/C4*365)*-1 -> 46.97432 | P8: =(D8/D4*365)*-1 -> 46.486712 | Q8: =(E8/E4*365)*-1 -> 46.394452
A9: Days Outstanding- inv | B9: =N8 -> 42.795819 | C9: =O8 -> 46.97432 | D9: =P8 -> 46.486712 | E9: =Q8 -> 46.394452 | F9: 46 | G9: 46 | H9: 46 | I9: 46 | J9: 46 | K9: 46
A10: Prepaid expenses | B10: ='Balance Sheet'!C21 -> 980 | C10: ='Balance Sheet'!D21 -> 806 | D10: ='Balance Sheet'!E21 -> 798 | E10: ='Balance Sheet'!F21 -> 921 | F10: =F3*F11 -> 973.6524 | G10: =G3*G11 -> 1032.0715 | H10: =H3*H11 -> 1093.9958 | I10: =I3*I11 -> 1159.6356 | J10: =J3*J11 -> 1229.2137 | K10: =K3*K11 -> 1302.9665 | M10: Prepaid % of sales | N10: =B10/B3 -> 0.012331077 | O10: =C10/C3 -> 0.0093295676 | P10: =D10/D3 -> 0.0087240765 | Q10: =E10/E3 -> 0.010026782
A11: % Sales | B11: =N10 -> 0.012331077 | C11: =O10 -> 0.0093295676 | D11: =P10 -> 0.0087240765 | E11: =Q10 -> 0.010026782 | F11: 0.01 | G11: 0.01 | H11: 0.01 | I11: 0.01 | J11: 0.01 | K11: 0.01
A12: Other assets | B12: ='Balance Sheet'!C19 -> 392 | C12: ='Balance Sheet'!D19 -> 394 | D12: ='Balance Sheet'!E19 -> 292 | E12: ='Balance Sheet'!F19 -> 761 | F12: =F3*F13 -> 681.55668 | G12: =G3*G13 -> 722.45008 | H12: =H3*H13 -> 765.79709 | I12: =I3*I13 -> 811.74491 | J12: =J3*J13 -> 860.44961 | K12: =K3*K13 -> 912.07658 | M12: Other Asset % of sales | N12: =B12/B3 -> 0.0049324307 | O12: =C12/C3 -> 0.0045606075 | P12: =D12/D3 -> 0.0031922686 | Q12: =E12/E3 -> 0.0082848869
A13: %0f Sales | B13: =N12 -> 0.0049324307 | C13: =O12 -> 0.0045606075 | D13: =P12 -> 0.0031922686 | E13: =Q12 -> 0.0082848869 | F13: 0.007 | G13: 0.007 | H13: 0.007 | I13: 0.007 | J13: 0.007 | K13: 0.007
A14: Total non cash Asset | B14: =B6+B8+B10+B12 -> 14399 | C14: =C6+C8+C10+C12 -> 16585 | D14: =D6+D8+D10+D12 -> 17239 | E14: =E6+E8+E10+E12 -> 17321 | F14: =F6+F8+F10+F12 -> 17860.634 | G14: =G6+G8+G10+G12 -> 18932.272 | H14: =H6+H8+H10+H12 -> 20068.209 | I14: =I6+I8+I10+I12 -> 21272.301 | ... K14: =K6+K8+K10+K12 -> 23901.558
A16: Accounts Payable and other Accruals | B16: ='Balance Sheet'!C36 -> 21159 | C16: ='Balance Sheet'!D36 -> 23371 | D16: ='Balance Sheet'!E36 -> 25137 | E16: ='Balance Sheet'!F36 -> 24454 | F16: =F3*F17/365 -> 26141.9 | G16: =G3*G17/365 -> 27710.414 | H16: =H3*H17/365 -> 29373.039 | I16: =I3*I17/365 -> 31135.421 | J16: =J3*J17/365 -> 33003.547 | K16: =K3*K17/365 -> 34983.759 | M16: Account payable days | N16: =B16/B3*365 -> 97.176875 | O16: =C16/C3*365 -> 98.740798 | P16: =D16/D3*365 -> 100.30507 | Q16: =E16/E3*365 -> 97.172796
A17: Days outstanding | B17: =N16 -> 97.176875 | C17: =O16 -> 98.740798 | D17: =P16 -> 100.30507 | E17: =Q16 -> 97.172796 | F17: 98 | G17: 98 | H17: 98 | I17: 98 | J17: 98 | K17: 98
A19: Total current liability | B19: =B16 -> 21159 | C19: =C16 -> 23371 | D19: =D16 -> 25137 | E19: =E16 -> 24454 | F19: =F16 -> 26141.9 | G19: =G16 -> 27710.414 | H19: =H16 -> 29373.039 | I19: =I16 -> 31135.421 | ... K19: =K16 -> 34983.759
A20: Working capital | B20: =B14-B19 -> -6760 | C20: =C14-C19 -> -6786 | D20: =D14-D19 -> -7898 | E20: =E14-E19 -> -7133 | F20: =F14-F19 -> -8281.2658 | G20: =G14-G19 -> -8778.1417 | H20: =H14-H19 -> -9304.8302 | I20: =I14-I19 -> -9863.12 | ... K20: =K14-K19 -> -11082.202
A22: Increase or decrease | C22: =(B14-C14)+(C19-B19) -> 26 | D22: =(C14-D14)+(D19-C19) -> 1112 | E22: =(D14-E14)+(E19-D19) -> -765 | F22: =(E14-F14)+(F19-E19) -> 1148.2658 | G22: =(F14-G14)+(G19-F19) -> 496.87595 | H22: =(G14-H14)+(H19-G19) -> 526.6885 | I22: =(H14-I14)+(I19-H19) -> 558.28981 | J22: =(I14-J14)+(J19-I19) -> 591.7872 | K22: =(J14-K14)+(K19-J19) -> 627.29443

Sheet PPE Schedule
B2: PPE Schedule
B4: ='Income Statement'!B4 -> (YE 31-Dec, USDm) | C4: ='Income Statement'!C4 -> FY 2021 | D4: ='Income Statement'!D4 -> FY 2022 | E4: fy2023 | F4: ='Income Statement'!F4 -> FY 2024 | G4: ='Income Statement'!G4 -> FY 2025 E | H4: ='Income Statement'!H4 -> FY 2026(E) | I4: ='Income Statement'!I4 -> FY 2027E | J4: ='Income Statement'!J4 -> FY 2028 E | K4: ='Income Statement'!K4 -> FY 2029 E | L4: ='Income Statement'!L4 -> FY 2030 E
B6: Total Sales (Revenue) | C6: ='Income Statement'!C6 -> 79474 | D6: ='Income Statement'!D6 -> 86392 | E6: ='Income Statement'!E6 -> 91471 | F6: ='Income Statement'!F6 -> 91854 | G6: ='Income Statement'!G6 -> 97365.24 | H6: ='Income Statement'!H6 -> 103207.15 | I6: ='Income Statement'!I6 -> 109399.58 | J6: ='Income Statement'!J6 -> 115963.56 | ... L6: ='Income Statement'!L6 -> 130296.65
B7: Opening Balance | C7: 21369 | D7: =C13 -> 22407 | E7: =D13 -> 24291 | F7: =E13 -> 27039 | G7: =F13 -> 28008 | H7: =G13 -> 30602.374 | I7: =H13 -> 33256.451 | J7: =I13 -> 35983.89 | K7: =J13 -> 38798.11 | L7: =K13 -> 41712.389
B8: (+) Additions (Capex) | C8: ='Cash Flow Statement'!C19*-1 -> 4625 | D8: ='Cash Flow Statement'!D19*-1 -> 5207 | E8: ='Cash Flow Statement'!E19*-1 -> 5518 | F8: ='Cash Flow Statement'!F19*-1 -> 5318 | G8: ='Income Statement'!G6*'PPE Schedule'!G9 -> 5841.9144 | H8: ='Income Statement'!H6*'PPE Schedule'!H9 -> 6192.4293 | I8: ='Income Statement'!I6*'PPE Schedule'!I9 -> 6563.975 | J8: ='Income Statement'!J6*'PPE Schedule'!J9 -> 6957.8135 | K8: ='Income Statement'!K6*'PPE Schedule'!K9 -> 7375.2823 | L8: ='Income Statement'!L6*'PPE Schedule'!L9 -> 7817.7993
B9: % of Sales | C9: =C8/'Income Statement'!C6 -> 0.058195133 | D9: =D8/'Income Statement'!D6 -> 0.060271784 | E9: =E8/'Income Statement'!E6 -> 0.06032513 | F9: =F8/'Income Statement'!F6 -> 0.057896227 | G9: 0.06 | H9: 0.06 | I9: 0.06 | J9: 0.06 | K9: 0.06 | L9: 0.06
B10: (-) /+Sale (adj) | C10: 877 | D10: 560 | E10: -178 | F10: 1189 | G10: 0 | H10: 0 | I10: 0 | J10: 0 | K10: 0 | L10: 0
B11: (-) Depreciation | C11: ='Cash Flow Statement'!C8 -> 2710 | D11: ='Cash Flow Statement'!D8 -> 2763 | E11: ='Cash Flow Statement'!E8 -> 2948 | F11: ='Cash Flow Statement'!F8 -> 3160 | G11: =(G7+G8/2)*G12 -> 3247.5405 | H11: =(H7+H8/2)*H12 -> 3538.3518 | I11: =(I7+I8/2)*I12 -> 3836.5361 | J11: =(J7+J8/2)*J12 -> 4143.5937 | K11: =(K7+K8/2)*K12 -> 4461.0039 | L11: =(L7+L8/2)*L12 -> 4790.2353
B12: % of opening balance+capex/2 | C12: =C11/(C7+C8/2) -> 0.11443532 | D12: =D11/(D7+D8/2) -> 0.1104736 | E12: =E11/(E7+E8/2) -> 0.10898336 | F12: =F11/(F7+F8/2) -> 0.10640447 | G12: 0.105 | H12: 0.105 | I12: 0.105 | J12: 0.105 | K12: 0.105 | L12: 0.105
B13: Closing Balance | C13: =C7+C8-C10-C11 -> 22407 | D13: =D7+D8-D10-D11 -> 24291 | E13: =E7+E8-E10-E11 -> 27039 | F13: =F7+F8-F10-F11 -> 28008 | G13: =G7+G8-G10-G11 -> 30602.374 | H13: =H7+H8-H10-H11 -> 33256.451 | I13: =I7+I8-I10-I11 -> 35983.89 | J13: =J7+J8-J10-J11 -> 38798.11 | ... L13: =L7+L8-L10-L11 -> 44739.953
B17: Assumptions-

Sheet Debt Schedule
B2: Debt Schedule
B4: ='Income Statement'!B4 -> (YE 31-Dec, USDm) | C4: ='Income Statement'!C4 -> FY 2021 | D4: ='Income Statement'!D4 -> FY 2022 | E4: ='Income Statement'!E4 -> FY 2023 | F4: ='Income Statement'!F4 -> FY 2024 | G4: ='Income Statement'!G4 -> FY 2025 E | H4: ='Income Statement'!H4 -> FY 2026(E) | I4: ='Income Statement'!I4 -> FY 2027E | ... L4: ='Income Statement'!L4 -> FY 2030 E
B5: Cash available
B6: From Operating cashflow | C6: ='Cash Flow Statement'!C17 -> 11616 | D6: ='Cash Flow Statement'!D17 -> 10811 | E6: ='Cash Flow Statement'!E17 -> 13442 | F6: ='Cash Flow Statement'!F17 -> 12507 | G6: ='Cash Flow Statement'!G17 -> 15083.922 | H6: ='Cash Flow Statement'!H17 -> 15427.948 | I6: ='Cash Flow Statement'!I17 -> 16502.826 | J6: ='Cash Flow Statement'!J17 -> 17633.179 | ... L6: ='Cash Flow Statement'!L17 -> 20077.568
B7: From Investing Activity | C7: ='Cash Flow Statement'!C22 -> -3269 | D7: ='Cash Flow Statement'!D22 -> -2430 | E7: ='Cash Flow Statement'!E22 -> -5495 | F7: ='Cash Flow Statement'!F22 -> -5472 | G7: ='Cash Flow Statement'!G22 -> -5841.9144 | H7: ='Cash Flow Statement'!H22 -> -6192.4293 | I7: ='Cash Flow Statement'!I22 -> -6563.975 | J7: ='Cash Flow Statement'!J22 -> -6957.8135 | ... L7: ='Cash Flow Statement'!L22 -> -7817.7993
B9: Beginning Cash | C9: ='Cash Flow Statement'!C34 -> 8254 | D9: ='Cash Flow Statement'!D34 -> 5596 | E9: ='Cash Flow Statement'!E34 -> 4954 | F9: ='Cash Flow Statement'!F34 -> 9711 | G9: ='Cash Flow Statement'!G34 -> 8505 | H9: ='Cash Flow Statement'!H34 -> 2638.3725 | I9: ='Cash Flow Statement'!I34 -> 3318.1074 | J9: ='Cash Flow Statement'!J34 -> 4140.2766 | ... L9: ='Cash Flow Statement'!L34 -> 6210.9498
B10: Minimum Cash | G10: -1000 | H10: -1000 | I10: -1000 | J10: -1000 | K10: -1000 | L10: -1000
B11: Dividend Payment | C11: ='Cash Flow Statement'!C28 -> -5815 | D11: ='Cash Flow Statement'!D28 -> -6172 | E11: ='Cash Flow Statement'!E28 -> -6682 | F11: ='Cash Flow Statement'!F28 -> -7229 | G11: ='Cash Flow Statement'!G28 -> -8026.6346 | H11: ='Cash Flow Statement'!H28 -> -8555.7837 | I11: ='Cash Flow Statement'!I28 -> -9116.6818 | J11: ='Cash Flow Statement'!J28 -> -9711.2337 | ... L11: ='Cash Flow Statement'!L28 -> -11009.497
B12: Term debt payment | C12: ='Cash Flow Statement'!C27 -> -3455 | D12: ='Cash Flow Statement'!D27 -> -2458 | E12: ='Cash Flow Statement'!E27 -> -3005 | F12: ='Cash Flow Statement'!F27 -> -3886 | G12: =(G17*G13)*-1 -> 0 | H12: =(H17*H13)*-1 -> 0 | I12: =(I17*I13)*-1 -> 0 | J12: =(J17*J13)*-1 -> 0 | K12: =(K17*K13)*-1 -> 0 | L12: =(L17*L13)*-1 -> 0
B14: Cash left for other repayment | G14: =SUM(G6:G12) -> 8720.3725 | H14: =SUM(H6:H12) -> 2318.1074 | I14: =SUM(I6:I12) -> 3140.2766 | J14: =SUM(J6:J12) -> 4104.4085 | K14: =SUM(K6:K12) -> 5210.9498 | L14: =SUM(L6:L12) -> 6461.2218
B16: Term Debt
B17: Beginning | C17: 40370 | D17: =C19 -> 36026 | E17: =D19 -> 35657 | F17: =E19 -> 37595 | G17: =F19 -> 37224 | H17: =G19 -> 37224 | I17: =H19 -> 37224 | J17: =I19 -> 37224 | K17: =J19 -> 37224 | L17: =K19 -> 37224
B18: Repayment | G18: =G12 -> 0 | H18: =H12 -> 0 | I18: =I12 -> 0 | J18: =J12 -> 0 | K18: =K12 -> 0 | L18: =L12 -> 0
B19: Ending | C19: ='Balance Sheet'!C32 -> 36026 | D19: ='Balance Sheet'!D32 -> 35657 | E19: ='Balance Sheet'!E32 -> 37595 | F19: ='Balance Sheet'!F32 -> 37224 | G19: =G17+G18 -> 37224 | H19: =H17+H18 -> 37224 | I19: =I17+I18 -> 37224 | J19: =J17+J18 -> 37224 | K19: =K17+K18 -> 37224 | L19: =L17+L18 -> 37224
B22: Revolver Mechanism(Short term debt)
B23: Opening balance | G23: ='Balance Sheet'!F37 -> 7082 | H23: =G26 -> 0 | I23: =H26 -> 0 | J23: =I26 -> 0 | K23: =J26 -> 0 | L23: =K26 -> 0
B24: Repayment | G24: =IF(G14>0,MIN(G14,G23),0) -> 7082 | H24: =IF(H14>0,MIN(H14,H23),0) -> 0 | I24: =IF(I14>0,MIN(I14,I23),0) -> 0 | J24: =IF(J14>0,MIN(J14,J23),0) -> 0 | K24: =IF(K14>0,MIN(K14,K23),0) -> 0 | L24: =IF(L14>0,MIN(L14,L23),0) -> 0
B25: Borrowing | G25: =IF(G14<0, ABS(G14),0) -> 0 | H25: =IF(H14<0, ABS(H14),0) -> 0 | I25: =IF(I14<0, ABS(I14),0) -> 0 | J25: =IF(J14<0, ABS(J14),0) -> 0 | K25: =IF(K14<0, ABS(K14),0) -> 0 | L25: =IF(L14<0, ABS(L14),0) -> 0
B26: Closing balance(Revolver Facility) | G26: =G23-G24+G25 -> 0 | H26: =H23-H24+H25 -> 0 | I26: =I23-I24+I25 -> 0 | J26: =J23-J24+J25 -> 0 | K26: =K23-K24+K25 -> 0 | L26: =L23-L24+L25 -> 0
B28: Interest Calculation
B29: Interest on debt | C29: =-'Income Statement'!C23 -> 1863 | D29: =-'Income Statement'!D23 -> 939 | E29: =-'Income Statement'!E23 -> 819 | F29: =-'Income Statement'!F23 -> 919 | G29: =G19*G30 -> 1302.84 | H29: =H19*H30 -> 1302.84 | I29: =I19*I30 -> 1302.84 | J29: =J19*J30 -> 1302.84 | K29: =K19*K30 -> 1302.84 | L29: =L19*L30 -> 1302.84
B30: % of Term debt | C30: =C29/((C17+C19)*0.5) -> 0.048772187 | D30: =D29/((D17+D19)*0.5) -> 0.02619868 | E30: =E29/((E17+E19)*0.5) -> 0.022361164 | F30: =F29/((F17+F19)*0.5) -> 0.024565952 | G30: 0.035 | H30: 0.035 | I30: 0.035 | J30: 0.035 | K30: 0.035 | L30: 0.035

Sheet DCF
A1: Juice Co.
A2: Discounted Cash Flow
A4: ='Balance Sheet'!B4 -> (YE 31-Dec, USDm)
C5: 1 | D5: 2 | E5: 3 | F5: =+E5+1 -> 4 | G5: =+F5+1 -> 5 | H5: =+G5+1 -> 6
B6: ='Income Statement'!F4 -> FY 2024 | C6: ='Income Statement'!G4 -> FY 2025 E | D6: ='Income Statement'!H4 -> FY 2026(E) | E6: ='Income Statement'!I4 -> FY 2027E | F6: ='Income Statement'!J4 -> FY 2028 E | G6: ='Income Statement'!K4 -> FY 2029 E | H6: ='Income Statement'!L4 -> FY 2030 E
A8: Ebit | B8: ='Income Statement'!F20 -> 12865 | C8: ='Income Statement'!G20 -> 14498.044 | D8: ='Income Statement'!H20 -> 15367.927 | E8: ='Income Statement'!I20 -> 16290.002 | F8: ='Income Statement'!J20 -> 17267.402 | G8: ='Income Statement'!K20 -> 18303.447 | H8: ='Income Statement'!L20 -> 19401.653
A9: Ebit(1-t) | B9: =B8*(1+'Income Statement'!F29) -> 10366.524 | C9: =C8*(1+'Income Statement'!G29) -> 11743.416 | D9: =D8*(1+'Income Statement'!H29) -> 12448.021 | E9: =E8*(1+'Income Statement'!I29) -> 13194.902 | F9: =F8*(1+'Income Statement'!J29) -> 13986.596 | G9: =G8*(1+'Income Statement'!K29) -> 14825.792 | H9: =H8*(1+'Income Statement'!L29) -> 15715.339
A10: Add : D&A | B10: ='Income Statement'!F35 -> 3160 | C10: ='Income Statement'!G35 -> 3247.5405 | D10: ='Income Statement'!H35 -> 3538.3518 | E10: ='Income Statement'!I35 -> 3836.5361 | F10: ='Income Statement'!J35 -> 4143.5937 | G10: ='Income Statement'!K35 -> 4461.0039 | H10: ='Income Statement'!L35 -> 4790.2353
A12: Less:Capex | B12: ='Income Statement'!F36 -> 5318 | C12: ='Income Statement'!G36 -> 5841.9144 | D12: ='Income Statement'!H36 -> 6192.4293 | E12: ='Income Statement'!I36 -> 6563.975 | F12: ='Income Statement'!J36 -> 6957.8135 | G12: ='Income Statement'!K36 -> 7375.2823 | H12: ='Income Statement'!L36 -> 7817.7993
A14: NWC change | B14: ='Working capital'!E22 -> -765 | C14: ='Working capital'!F22 -> 1148.2658 | D14: ='Working capital'!G22 -> 496.87595 | E14: ='Working capital'!H22 -> 526.6885 | F14: ='Working capital'!I22 -> 558.28981 | G14: ='Working capital'!J22 -> 591.7872 | H14: ='Working capital'!K22 -> 627.29443
A16: FCFF | B16: =B9+B10-B12+B14 -> 7443.5235 | C16: =C9+C10-C12+C14 -> 10297.308 | D16: =D9+D10-D12+D14 -> 10290.819 | E16: =E9+E10-E12+E14 -> 10994.151 | F16: =F9+F10-F12+F14 -> 11730.666 | G16: =G9+G10-G12+G14 -> 12503.3 | H16: =H9+H10-H12+H14 -> 13315.07
A17: Terminal Value | C17: 0 | D17: 0 | E17: 0 | F17: 0 | G17: 0 | H17: =H16*(1+B55)/(B46-B55) -> 277170.84
A21: PepsiCo Wacc Calculation
A22: 1.Cost of equity(ke)-CAPm | B22: Value | C22: Sources
A23: Risk-Free Rate(Rf) | B23: 0.0402 | C23: US 10 Year Yield
A24: Beta (b) | B24: 0.55 | C24: Investing.com
A25: Market Risk Premium (Rm) | B25: 0.07 | C25: Standard Market Assumptions
A27: Cost of Equity (Ke) | B27: =B23+(B24*(B25)) -> 0.0787 | C27: Rf+(b*Rm)
A29: 2.Cost of debt (Kd) | B29: Value | C29: Source
A31: Pre-tax Cost of debt | B31: 0.035 | C31: (Historical debt cost for pepsi)
A32: Marginal-tax rate | B32: 0.19 | C32: (Based on historical data)
A33: After Tax Cost of debt | B33: =B31*(1-B32) -> 0.02835 | C33: Formula=B31*(1-B32)
A35: 3.Capital Structure(Weights) | B35: Value | C35: Source
A37: Share Price(P) | B37: $148.00 | C37: Current Price
A38: Shares outstanding | B38: 1372 M | C38: Q4 2024
A39: Market Value of Equity | B39: $203056 M
A40: Total Debt(D) | B40: $51400 M | C40: Q4 2024
A41: Total Capital | B41: $254456 M | C41: E+D
A42: Weight Of Equity (We) | B42: 0.798
A43: Weight Of Debt (Wd) | B43: 0.202
A45: Final Wacc
A46: WACC | B46: 0.069 | C46: =(B27*B42)+(B33*B43) -> 0.0685293
A50: Terminal Value
A51: Input & Assumptions | B51: Value | C51: Source
A53: Final Forecast Year FCF | B53: =H16 -> 13315.07 | C53: FCF 2030 E
A54: WACC® | B54: =B46 -> 0.069
A55: Terminal Growth Rate(g) | B55: 0.02 | C55: Assumption =US GDP
A56: Final Year EBITDA | B56: ='Income Statement'!L20+H10 -> 24191.889 | G56: Sensitivity Table
A57: Exit Multiple | B57: 14.5x | C57: Assumption | G57: WACC
F58: =B71 -> 144.12087 | G58: 0.06 | H58: 0.065 | I58: 0.069 | J58: =+I58+0.01 -> 0.079 | K58: =+J58+0.01 -> 0.089
...

Sheet Football Field
C4: FY1 | D4: =+DCF!$C$8 -> 14498.044
C6: Trading Comps FY+1 EBITDA | D6: =+G6*J6 -> 144980.44 | E6: =+F6-D6 -> 28996.088 | F6: =+H6*J6 -> 173976.53 | G6: 10 | H6: 12 | I6: FY+1 EBITDA | J6: =+DCF!C8 -> 14498.044
C7: DCF | D7: 550 | E7: =+F7-D7 -> 200 | F7: 750 | G7: 10-12% WACC, 1.5-2.5% PGR
C8: FCFE | D8: 510 | E8: =+F8-D8 -> 70 | F8: 580 | G8: 14-16% CoE, 1.5-2.5% PGR
C9: LBO (5 year exit) | D9: 440 | E9: =+F9-D9 -> 50 | F9: 490 | G9: 5 Year exit, Exit Multiple = 12x, Returns: 20-25%
C14: =+C9 -> LBO (5 year exit) | D14: =+D9 -> 440 | E14: =+E9 -> 50
C15: =+C8 -> FCFE | D15: =+D8 -> 510 | E15: =+E8 -> 70
C16: =+C7 -> DCF | D16: =+D7 -> 550 | E16: =+E7 -> 200
C17: =+C6 -> Trading Comps FY+1 EBITDA | D17: =+D6 -> 144980.44 | E17: =+E6 -> 28996.088
C21: Trading Comps FY+1 EBITDA | D21: =D6/$D$4 -> 10 | F21: =F6/$D$4 -> 12 | J21: 400 | K21: 750
C22: DCF | D22: =D7/$D$4 -> 0.037936152 | F22: =F7/$D$4 -> 0.051731116 | J22: =+J21/DCF!$C$8 -> 0.027589929 | K22: =+K21/DCF!$C$8 -> 0.051731116
C23: FCFE | D23: =D8/$D$4 -> 0.035177159 | F23: =F8/$D$4 -> 0.040005397
C24: LBO (5 year exit) | D24: =D9/$D$4 -> 0.030348922 | F24: =F9/$D$4 -> 0.033797663

Sheet Charts
C2: 300 | D2: =+C2+100 -> 400 | E2: =+D2+100 -> 500 | F2: =+E2+100 -> 600 | G2: =+F2+100 -> 700 | H2: =+G2+100 -> 800
A3: FY1 | B3: =+DCF!$C$8 -> 14498.044 | C3: =C2/$B$3 -> 0.020692447 | D3: =D2/$B$3 -> 0.027589929 | E3: =E2/$B$3 -> 0.034487411 | F3: =F2/$B$3 -> 0.041384893 | G3: =G2/$B$3 -> 0.048282375 | H3: =H2/$B$3 -> 0.055179857
A4: FY2 | B4: =+DCF!$D$8 -> 15367.927 | C4: =C2/$B$4 -> 0.019521176 | D4: =D2/$B$4 -> 0.026028235 | E4: =E2/$B$4 -> 0.032535293 | F4: =F2/$B$4 -> 0.039042352 | G4: =G2/$B$4 -> 0.045549411 | H4: =H2/$B$4 -> 0.052056469
